Workbook

Sheet Main Report (2)
M1: CL-F08
A2: Final Inspection Report BIÊN BẢN KIỂM TRA FINAL
A3: Loại kiểm tra : | C3: Inline | E3: Pre-Final | F3: FALSE | I3: Final | K3: AQL 2.5 | M3: FALSE
A4: Customer (KH): | C4: PO : | F4: Style (mã hàng): | L4: Date (Ngày) :
A5: Order Qty (SL) : | B5: 20000 | C5: Sample size (SL mẫu) : | E5: =VLOOKUP(B5,H94:I103,2,1) -> 315 | F5: Shipment date : Ngày xuất | I5: MDA# : | L5: Inspector : Người kiểm tra:
A6: Factory Details | B6: Supplier : NHA BE | E6: Fty Name : | I6: Location : VIET NAM
A7: Production status Tình trạng SX | B7: Cutting Qty: SL cắt : | D7: Sewing Qty: SL may: | F7: Pressing Qty: SL ủi, ập: | H7: Packing Qty: SL đóng gói:
A8: MATERIALS | C8: v | D8: X | G8: v | H8: X | L8: v | M8: X
A9: 1. Fabric - Vải | E9: 3. Accesories / Trims - Phụ liệu | I9: 5. Packing - Đóng gói
A10: Fabric Qlty (CL vải chính) | C10: v | E10: Zipper | F10: Dây kéo | I10: Unit packed - SL đóng | L10: v
A11: Handfeel (Độ cảm nhận) | C11: v | E11: Button/ button hole - Khuy/nút | G11: v | I11: Folding method - Gấp xếp | L11: v
A12: Contrast fabric | C12: v | E12: Snap / button - Nút đóng | G12: v | I12: Cardboard size & qlty - CL và size bìa | L12: v
A13: Lining Qlty (CL lót) | C13: v | E13: Rivet - Ri vê | I13: Polybag size & qlty - CL và size bao nylon | L13: v
A14: Lining Colour (màu lót) | C14: v | E14: Eyelet | F14: Mắt cáo | I14: Box size & qlty - CL và size thùng | L14: v
E15: Buckle - Khóa chốt | I15: Box end label - Nhãn thùng
E16: Piping - Viền | I16: Gross weight < 15Kg
A17: 2. Colours - Màu sắc | E17: Threads | F17: Chỉ | G17: v | I17: Sealing tape - Keo dán thùng | L17: v
A18: Colour as lab dip - So bảng màu | C18: v | I18: Ration pack sticker - Tỷ lệ trên nhãn | L18: v
A19: Matching tones - Tông màu | C19: v | E19: Labels & APPEARANCE | I19: Flat Packed - Đóng phẳng | L19: v
A20: Colour fastness - Bền màu | C20: v | E20: Main label - Nhãn chính | G20: v | I20: Hanging goods - Hàng treo | L20: v
A21: Printing - In | E21: Size label - Nhãn size | G21: v | I21: Gross weight < 22Kg
A22: Embroidery - Thêu | E22: Care label - Nhãn care | G22: v | I22: Box hanger - Hàng treo dạng hộp
A23: Shade Band - Ánh màu | C23: v | E23: Hang tag - Nhãn treo | G23: v
E24: Price label - Nhãn giá | G24: v
A26: INSPECTION POINTS( Những Điểm Kiểm Tra ) | G26: OK | H26: Major Lỗi nặng | I26: Minor Lỗi nhẹ | J26: Remarks ( Ghi chú )
A27: 1. FABRIC DEFECTS / LỖI VẢI
A28: A. Shell - Flaw / Fibre def. / Hole. Lớp vỏ - xước / lỗi sợi / lủng lỗ. )
A29: B. Linning - Flaw / Fibre def. / Hole.( Lớp lót - Xước /Lỗi sợi / Lủng lỗ.)
A30: C .Mismatch of Stripes. (Canh sọc.)
A31: D. Puckers/Creases ( Nhàu/Nhăn/Nếp gấp )
A32: E. Shading (Loang màu.)
A33: F. Others (Các lỗi khác) | H33: 2
A34: 2. CONSTRUCTION& STITCHING/LỖI KẾT CẤU & Đ.MAY | I34: 2
A35: A. Run of topstitching ( Lệch đường may diễu )
A36: B. Seam twisted/puckered/pleated (Đường may vặn/xoắn/nhăn/xếp ly)
A37: C. Skip/Broken stitches ( Bỏ mũi/Đứt chỉ )
A38: D. Tight / Loose tension (Đường may căng / lỏng chỉ.)
A39: E. Seam not straight (Đ.may không thẳng )
A40: F. Stitches per inch/cm ( Sai số mũi trên 1” hoặc 1 cm.)
A41: G. Insecure stitch endings (Lại mũi không đảm bảo.)
...

Sheet Measurement sheet
A1: Measurement sheet
A2: Customer (KH): | C2: ='Main Report (2)'!B4 | E2: Style (mã hàng): | G2: ='Main Report (2)'!H4 | L2: PO : | M2: ='Main Report (2)'!D4
A3: Order Qty (SL) : | C3: ='Main Report (2)'!B5 -> 20000 | E3: Sample size (SL mẫu) : | G3: ='Main Report (2)'!E5 -> 315 | I3: MDA# : | J3: ='Main Report (2)'!J5 | O3: Shipment date : | Q3: ='Main Report (2)'!H5 | R3: Date (Ngày) : | S3: ='Main Report (2)'!M4

Sheet Details of style
A1: Details Description
A2: =#REF! -> #REF! | G2: =#REF! -> #REF! | N2: =#REF! -> #REF!
A3: =#REF! -> #REF! | G3: =#REF! -> #REF! | K3: =#REF! -> #REF! | N3: ='Measurement sheet'!#REF! -> NaN | O3: ='Measurement sheet'!#REF! -> #ERROR! | W3: Date : | X3: ='Measurement sheet'!#REF! -> NaN
A17: Product - Front | G17: Product - Back | M17: All colors of Product | S17: Sealer Sample
A31: Main label | G31: Care label - Front | M31: Care label - Back | S31: Swing ticket
A45: Carton stacking | G45: Box end label

Sheet Picture Major Defects 
A1: Picture Major Defects
A2: Customer (KH): | C2: ='Measurement sheet'!C2 | E2: Style (mã hàng): | G2: ='Measurement sheet'!G2 | L2: PO : | M2: ='Measurement sheet'!M2
A3: Order Qty (SL) : | C3: ='Measurement sheet'!C3 -> 20000 | E3: Sample size (SL mẫu) : | G3: ='Measurement sheet'!G3 -> 315 | I3: MDA# : | J3: ='Main Report (2)'!J5 | O3: Shipment date : | Q3: ='Measurement sheet'!Q3 | R3: Date (Ngày) : | S3: ='Measurement sheet'!S3
A12: Defect: | F12: Defect: | K12: Defect: | P12: Defect:
P13: `
A21: Defect: | F21: Defect: | K21: Defect: | P21: Defect:
A30: Defect: | F30: Defect: | K30: Defect: | P30: Defect:
A39: Defect: | F39: Defect: | K39: Defect: | P39: Defect:

Sheet Picture Minor Defects
A2: Customer (KH): | C2: ='Picture Major Defects '!C2 | E2: Style (mã hàng): | G2: ='Picture Major Defects '!G2 | L2: PO : | M2: ='Picture Major Defects '!M2
A3: Order Qty (SL) : | C3: ='Picture Major Defects '!C3 -> 20000 | E3: Sample size (SL mẫu) : | G3: ='Picture Major Defects '!G3 -> 315 | I3: MDA# : | J3: ='Main Report (2)'!J5 | O3: Shipment date : | P3: ='Picture Major Defects '!Q3 | R3: Date (Ngày) : | S3: ='Picture Major Defects '!S3
A12: Defect: | F12: Defect: | K12: Defect: | P12: Defect:
A21: Defect: | F21: Defect: | K21: Defect: | P21: Defect:
A30: Defect: | F30: Defect: | K30: Defect: | P30: Defect:
A39: Defect: | F39: Defect: | K39: Defect: | P39: Defect:

Sheet picture accept
A1: PICTURE ACCEPT
A2: Customer (KH): | C2: ='Picture Major Defects '!C2 | E2: Style (mã hàng): | G2: ='Picture Major Defects '!G2 | L2: PO : | M2: ='Picture Major Defects '!M2
A3: Order Qty (SL) : | C3: ='Picture Major Defects '!C3 -> 20000 | E3: Sample size (SL mẫu) : | G3: ='Picture Major Defects '!G3 -> 315 | I3: MDA# : | J3: ='Main Report (2)'!J5 | O3: Shipment date : | Q3: ='Picture Major Defects '!Q3 | R3: Date (Ngày) : | S3: ='Picture Major Defects '!S3

Sheet Sheet1
